2021-11-16 11:57:52,177 INFO    MainThread:10488 [internal.py:wandb_internal():90] W&B internal server running at pid: 10488, started at: 2021-11-16 11:57:52.176405
2021-11-16 11:57:52,180 INFO    WriterThread:10488 [datastore.py:open_for_write():77] open: c:\Users\ruben\VDoomLearning\src\wandb\run-20211116_115748-38p5m4dp\run-38p5m4dp.wandb
2021-11-16 11:57:52,182 DEBUG   HandlerThread:10488 [handler.py:handle_request():130] handle_request: check_version
2021-11-16 11:57:52,190 DEBUG   SenderThread:10488 [sender.py:send():238] send: header
2021-11-16 11:57:52,191 DEBUG   SenderThread:10488 [sender.py:send_request():252] send_request: check_version
2021-11-16 11:57:53,589 DEBUG   SenderThread:10488 [sender.py:send():238] send: run
2021-11-16 11:57:53,593 INFO    SenderThread:10488 [sender.py:_maybe_setup_resume():506] checking resume status for None/VDoomLearning/38p5m4dp
2021-11-16 11:57:53,886 ERROR   SenderThread:10488 [internal_api.py:execute():144] 404 response executing GraphQL.
2021-11-16 11:57:53,886 ERROR   SenderThread:10488 [internal_api.py:execute():145] <!DOCTYPE html>
<html lang=en>
  <meta charset=utf-8>
  <meta name=viewport content="initial-scale=1, minimum-scale=1, width=device-width">
  <title>Error 404 (Not Found)!!1</title>
  <style>
    *{margin:0;padding:0}html,code{font:15px/22px arial,sans-serif}html{background:#fff;color:#222;padding:15px}body{margin:7% auto 0;max-width:390px;min-height:180px;padding:30px 0 15px}* > body{background:url(//www.google.com/images/errors/robot.png) 100% 5px no-repeat;padding-right:205px}p{margin:11px 0 22px;overflow:hidden}ins{color:#777;text-decoration:none}a img{border:0}@media screen and (max-width:772px){body{background:none;margin-top:0;max-width:none;padding-right:0}}#logo{background:url(//www.google.com/images/branding/googlelogo/1x/googlelogo_color_150x54dp.png) no-repeat;margin-left:-5px}@media only screen and (min-resolution:192dpi){#logo{background:url(//www.google.com/images/branding/googlelogo/2x/googlelogo_color_150x54dp.png) no-repeat 0% 0%/100% 100%;-moz-border-image:url(//www.google.com/images/branding/googlelogo/2x/googlelogo_color_150x54dp.png) 0}}@media only screen and (-webkit-min-device-pixel-ratio:2){#logo{background:url(//www.google.com/images/branding/googlelogo/2x/googlelogo_color_150x54dp.png) no-repeat;-webkit-background-size:100% 100%}}#logo{display:inline-block;height:54px;width:150px}
  </style>
  <a href=//www.google.com/><span id=logo aria-label=Google></span></a>
  <p><b>404.</b> <ins>That’s an error.</ins>
  <p>The requested URL <code>/graphql</code> was not found on this server.  <ins>That’s all we know.</ins>

2021-11-16 11:57:54,430 INFO    WriterThread:10488 [datastore.py:close():281] close: c:\Users\ruben\VDoomLearning\src\wandb\run-20211116_115748-38p5m4dp\run-38p5m4dp.wandb
2021-11-16 11:57:54,430 INFO    HandlerThread:10488 [handler.py:finish():731] shutting down handler
2021-11-16 11:57:54,430 ERROR   MainThread:10488 [internal.py:wandb_internal():158] Thread SenderThread:
Traceback (most recent call last):
  File "C:\Users\ruben\AppData\Local\Programs\Python\Python36\lib\site-packages\wandb\sdk\lib\retry.py", line 102, in __call__
    result = self._call_fn(*args, **kwargs)
  File "C:\Users\ruben\AppData\Local\Programs\Python\Python36\lib\site-packages\wandb\sdk\internal\internal_api.py", line 147, in execute
    six.reraise(*sys.exc_info())
  File "C:\Users\ruben\AppData\Local\Programs\Python\Python36\lib\site-packages\six.py", line 719, in reraise
    raise value
  File "C:\Users\ruben\AppData\Local\Programs\Python\Python36\lib\site-packages\wandb\sdk\internal\internal_api.py", line 141, in execute
    return self.client.execute(*args, **kwargs)
  File "C:\Users\ruben\AppData\Local\Programs\Python\Python36\lib\site-packages\wandb\vendor\gql-0.2.0\gql\client.py", line 52, in execute
    result = self._get_result(document, *args, **kwargs)
  File "C:\Users\ruben\AppData\Local\Programs\Python\Python36\lib\site-packages\wandb\vendor\gql-0.2.0\gql\client.py", line 60, in _get_result
    return self.transport.execute(document, *args, **kwargs)
  File "C:\Users\ruben\AppData\Local\Programs\Python\Python36\lib\site-packages\wandb\vendor\gql-0.2.0\gql\transport\requests.py", line 39, in execute
    request.raise_for_status()
  File "C:\Users\ruben\AppData\Local\Programs\Python\Python36\lib\site-packages\requests\models.py", line 953, in raise_for_status
    raise HTTPError(http_error_msg, response=self)
requests.exceptions.HTTPError: 404 Client Error: Not Found for url: https://api.wandb.ai/graphql

During handling of the above exception, another exception occurred:

Traceback (most recent call last):
  File "C:\Users\ruben\AppData\Local\Programs\Python\Python36\lib\site-packages\wandb\apis\normalize.py", line 24, in wrapper
    return func(*args, **kwargs)
  File "C:\Users\ruben\AppData\Local\Programs\Python\Python36\lib\site-packages\wandb\sdk\internal\internal_api.py", line 786, in run_resume_status
    variable_values={"entity": entity, "project": project_name, "name": name,},
  File "C:\Users\ruben\AppData\Local\Programs\Python\Python36\lib\site-packages\wandb\sdk\lib\retry.py", line 118, in __call__
    if not check_retry_fn(e):
  File "C:\Users\ruben\AppData\Local\Programs\Python\Python36\lib\site-packages\wandb\util.py", line 821, in no_retry_auth
    raise CommError("Permission denied, ask the project owner to grant you access")
wandb.errors.CommError: Permission denied, ask the project owner to grant you access

During handling of the above exception, another exception occurred:

Traceback (most recent call last):
  File "C:\Users\ruben\AppData\Local\Programs\Python\Python36\lib\site-packages\wandb\sdk\internal\internal_util.py", line 52, in run
    self._run()
  File "C:\Users\ruben\AppData\Local\Programs\Python\Python36\lib\site-packages\wandb\sdk\internal\internal_util.py", line 102, in _run
    self._process(record)
  File "C:\Users\ruben\AppData\Local\Programs\Python\Python36\lib\site-packages\wandb\sdk\internal\internal.py", line 291, in _process
    self._sm.send(record)
  File "C:\Users\ruben\AppData\Local\Programs\Python\Python36\lib\site-packages\wandb\sdk\internal\sender.py", line 240, in send
    send_handler(record)
  File "C:\Users\ruben\AppData\Local\Programs\Python\Python36\lib\site-packages\wandb\sdk\internal\sender.py", line 678, in send_run
    error = self._maybe_setup_resume(run)
  File "C:\Users\ruben\AppData\Local\Programs\Python\Python36\lib\site-packages\wandb\sdk\internal\sender.py", line 509, in _maybe_setup_resume
    entity=entity, project_name=run.project, name=run.run_id
  File "C:\Users\ruben\AppData\Local\Programs\Python\Python36\lib\site-packages\wandb\apis\normalize.py", line 62, in wrapper
    six.reraise(CommError, CommError(message, err), sys.exc_info()[2])
  File "C:\Users\ruben\AppData\Local\Programs\Python\Python36\lib\site-packages\six.py", line 718, in reraise
    raise value.with_traceback(tb)
  File "C:\Users\ruben\AppData\Local\Programs\Python\Python36\lib\site-packages\wandb\apis\normalize.py", line 24, in wrapper
    return func(*args, **kwargs)
  File "C:\Users\ruben\AppData\Local\Programs\Python\Python36\lib\site-packages\wandb\sdk\internal\internal_api.py", line 786, in run_resume_status
    variable_values={"entity": entity, "project": project_name, "name": name,},
  File "C:\Users\ruben\AppData\Local\Programs\Python\Python36\lib\site-packages\wandb\sdk\lib\retry.py", line 118, in __call__
    if not check_retry_fn(e):
  File "C:\Users\ruben\AppData\Local\Programs\Python\Python36\lib\site-packages\wandb\util.py", line 821, in no_retry_auth
    raise CommError("Permission denied, ask the project owner to grant you access")
wandb.errors.CommError: Permission denied, ask the project owner to grant you access
2021-11-16 11:57:56,479 INFO    MainThread:10488 [internal.py:handle_exit():77] Internal process exited
